<?xml version="1.0" encoding="utf-8"?>
<!-- This URDF was automatically created by SolidWorks to URDF Exporter! Originally created by Stephen Brawner (brawner@gmail.com) 
     Commit Version: 1.6.0-1-g15f4949  Build Version: 1.6.7594.29634
     For more information, please see http://wiki.ros.org/sw_urdf_exporter -->
<robot
  name="urdf_arm_manipulator">
  <link
    name="base_link">
    <inertial>
      <origin
        xyz="-0.00038925 0.019099 2.2211E-08"
        rpy="0 0 0" />
      <mass
        value="0.99888" />
      <inertia
        ixx="0.0015356"
        ixy="5.2783E-06"
        ixz="5.2648E-08"
        iyy="0.0033614"
        iyz="-7.8329E-10"
        izz="0.0020827" />
    </inertial>
    <visual>
      <origin
        xyz="0 0 0"
        rpy="0 0 0" />
      <geometry>
        <mesh
          filename="package://urdf_arm_manipulator/meshes/base_link.STL" />
      </geometry>
      <material
        name="">
        <color
          rgba="0.75294 0.75294 0.75294 1" />
      </material>
    </visual>
    <collision>
      <origin
        xyz="0 0 0"
        rpy="0 0 0" />
      <geometry>
        <mesh
          filename="package://urdf_arm_manipulator/meshes/base_link.STL" />
      </geometry>
    </collision>
  </link>
  <link
    name="link_1">
    <inertial>
      <origin
        xyz="0.00031031 0.017557 0.0085881"
        rpy="0 0 0" />
      <mass
        value="0.18582" />
      <inertia
        ixx="0.00011451"
        ixy="-8.3462E-14"
        ixz="1.6188E-07"
        iyy="0.00018668"
        iyz="2.4586E-06"
        izz="9.7067E-05" />
    </inertial>
    <visual>
      <origin
        xyz="0 0 0"
        rpy="0 0 0" />
      <geometry>
        <mesh
          filename="package://urdf_arm_manipulator/meshes/link_1.STL" />
      </geometry>
      <material
        name="">
        <color
          rgba="0.75294 0.75294 0.75294 1" />
      </material>
    </visual>
    <collision>
      <origin
        xyz="0 0 0"
        rpy="0 0 0" />
      <geometry>
        <mesh
          filename="package://urdf_arm_manipulator/meshes/link_1.STL" />
      </geometry>
    </collision>
  </link>
  <joint
    name="joint_1"
    type="continuous">
    <origin
      xyz="0 0 0.0465"
      rpy="1.5708 0 3.138" />
    <parent
      link="base_link" />
    <child
      link="link_1" />
    <axis
      xyz="0 1 0" />
  </joint>
  <link
    name="link_2">
    <inertial>
      <origin
        xyz="0.0005241 0.21494 0.0030261"
        rpy="0 0 0" />
      <mass
        value="0.17769" />
      <inertia
        ixx="0.00074438"
        ixy="1.9798E-13"
        ixz="3.1614E-07"
        iyy="0.00010123"
        iyz="6.591E-06"
        izz="0.00077654" />
    </inertial>
    <visual>
      <origin
        xyz="0 0 0"
        rpy="0 0 0" />
      <geometry>
        <mesh
          filename="package://urdf_arm_manipulator/meshes/link_2.STL" />
      </geometry>
      <material
        name="">
        <color
          rgba="0.75294 0.75294 0.75294 1" />
      </material>
    </visual>
    <collision>
      <origin
        xyz="0 0 0"
        rpy="0 0 0" />
      <geometry>
        <mesh
          filename="package://urdf_arm_manipulator/meshes/link_2.STL" />
      </geometry>
    </collision>
  </link>
  <joint
    name="joint_2"
    type="continuous">
    <origin
      xyz="0 0.0305 0"
      rpy="3.1416 0 -3.1416" />
    <parent
      link="link_1" />
    <child
      link="link_2" />
    <axis
      xyz="1 0 0" />
  </joint>
  <link
    name="link_3">
    <inertial>
      <origin
        xyz="0.00069544 0.19751 -0.0016747"
        rpy="0 0 0" />
      <mass
        value="0.1655" />
      <inertia
        ixx="0.00056833"
        ixy="3.1614E-07"
        ixz="-1.9962E-13"
        iyy="7.7094E-05"
        iyz="9.3981E-06"
        izz="0.00060632" />
    </inertial>
    <visual>
      <origin
        xyz="0 0 0"
        rpy="0 0 0" />
      <geometry>
        <mesh
          filename="package://urdf_arm_manipulator/meshes/link_3.STL" />
      </geometry>
      <material
        name="">
        <color
          rgba="0.75294 0.75294 0.75294 1" />
      </material>
    </visual>
    <collision>
      <origin
        xyz="0 0 0"
        rpy="0 0 0" />
      <geometry>
        <mesh
          filename="package://urdf_arm_manipulator/meshes/link_3.STL" />
      </geometry>
    </collision>
  </link>
  <joint
    name="joint_3"
    type="continuous">
    <origin
      xyz="0 0.2992 0.0316"
      rpy="0 0 0" />
    <parent
      link="link_2" />
    <child
      link="link_3" />
    <axis
      xyz="1 0 0" />
  </joint>
  <link
    name="link_4">
    <inertial>
      <origin
        xyz="-0.00031688 0.014002 -0.037776"
        rpy="0 0 0" />
      <mass
        value="0.071233" />
      <inertia
        ixx="2.3992E-05"
        ixy="1.0314E-08"
        ixz="1.4972E-09"
        iyy="2.3081E-05"
        iyz="1.883E-06"
        izz="2.9268E-05" />
    </inertial>
    <visual>
      <origin
        xyz="0 0 0"
        rpy="0 0 0" />
      <geometry>
        <mesh
          filename="package://urdf_arm_manipulator/meshes/link_4.STL" />
      </geometry>
      <material
        name="">
        <color
          rgba="0.75294 0.75294 0.75294 1" />
      </material>
    </visual>
    <collision>
      <origin
        xyz="0 0 0"
        rpy="0 0 0" />
      <geometry>
        <mesh
          filename="package://urdf_arm_manipulator/meshes/link_4.STL" />
      </geometry>
    </collision>
  </link>
  <joint
    name="joint_4"
    type="continuous">
    <origin
      xyz="0 0.2967 0.00185"
      rpy="-1.5708 0 -3.1416" />
    <parent
      link="link_3" />
    <child
      link="link_4" />
    <axis
      xyz="1 0 0" />
  </joint>
</robot>