<?xml version="1.0" encoding="utf-8"?>
<!-- This URDF was automatically created by SolidWorks to URDF Exporter! Originally created by Stephen Brawner (brawner@gmail.com) 
     Commit Version: 1.6.0-1-g15f4949  Build Version: 1.6.7594.29634
     For more information, please see http://wiki.ros.org/sw_urdf_exporter -->
<robot
  name="urdf_arm_manipulator">
  <link
    name="base_link">
    <inertial>
      <origin
        xyz="6.681E-17 -7.1316E-17 0.0015"
        rpy="0 0 0" />
      <mass
        value="0.11395" />
      <inertia
        ixx="0.00037683"
        ixy="2.7718E-20"
        ixz="-2.2805E-20"
        iyy="0.00037683"
        iyz="4.7115E-22"
        izz="0.00075349" />
    </inertial>
    <visual>
      <origin
        xyz="0 0 0"
        rpy="0 0 0" />
      <geometry>
        <mesh
          filename="package://urdf_arm_manipulator/meshes/base_link.STL" />
      </geometry>
      <material
        name="">
        <color
          rgba="0.79216 0.81961 0.93333 1" />
      </material>
    </visual>
    <collision>
      <origin
        xyz="0 0 0"
        rpy="0 0 0" />
      <geometry>
        <mesh
          filename="package://urdf_arm_manipulator/meshes/base_link.STL" />
      </geometry>
    </collision>
  </link>
  <link
    name="link_1">
    <inertial>
      <origin
        xyz="-0.013442 -0.0004857 0.021067"
        rpy="0 0 0" />
      <mass
        value="0.11872" />
      <inertia
        ixx="3.5872E-05"
        ixy="1.6188E-07"
        ixz="-2.4586E-06"
        iyy="5.3315E-05"
        iyz="8.2973E-14"
        izz="6.4574E-05" />
    </inertial>
    <visual>
      <origin
        xyz="0 0 0"
        rpy="0 0 0" />
      <geometry>
        <mesh
          filename="package://urdf_arm_manipulator/meshes/link_1.STL" />
      </geometry>
      <material
        name="">
        <color
          rgba="0.75294 0.75294 0.75294 1" />
      </material>
    </visual>
    <collision>
      <origin
        xyz="0 0 0"
        rpy="0 0 0" />
      <geometry>
        <mesh
          filename="package://urdf_arm_manipulator/meshes/link_1.STL" />
      </geometry>
    </collision>
  </link>
  <joint
    name="joint_1"
    type="continuous">
    <origin
      xyz="0 0 0.0495"
      rpy="0 0 0" />
    <parent
      link="base_link" />
    <child
      link="link_1" />
    <axis
      xyz="0 0 1" />
  </joint>
  <link
    name="link_2">
    <inertial>
      <origin
        xyz="0.0030261 0.0005241 0.21494"
        rpy="0 0 0" />
      <mass
        value="0.17769" />
      <inertia
        ixx="0.00077654"
        ixy="3.1614E-07"
        ixz="6.591E-06"
        iyy="0.00074438"
        iyz="1.9865E-13"
        izz="0.00010123" />
    </inertial>
    <visual>
      <origin
        xyz="0 0 0"
        rpy="0 0 0" />
      <geometry>
        <mesh
          filename="package://urdf_arm_manipulator/meshes/link_2.STL" />
      </geometry>
      <material
        name="">
        <color
          rgba="0.75294 0.75294 0.75294 1" />
      </material>
    </visual>
    <collision>
      <origin
        xyz="0 0 0"
        rpy="0 0 0" />
      <geometry>
        <mesh
          filename="package://urdf_arm_manipulator/meshes/link_2.STL" />
      </geometry>
    </collision>
  </link>
  <joint
    name="joint_2"
    type="continuous">
    <origin
      xyz="0 0 0.0255"
      rpy="0 0 0" />
    <parent
      link="link_1" />
    <child
      link="link_2" />
    <axis
      xyz="0 1 0" />
  </joint>
  <link
    name="link_3">
    <inertial>
      <origin
        xyz="-0.0016747 0.00069544 0.19751"
        rpy="0 0 0" />
      <mass
        value="0.1655" />
      <inertia
        ixx="0.00060632"
        ixy="-1.9865E-13"
        ixz="9.3981E-06"
        iyy="0.00056833"
        iyz="3.1614E-07"
        izz="7.7094E-05" />
    </inertial>
    <visual>
      <origin
        xyz="0 0 0"
        rpy="0 0 0" />
      <geometry>
        <mesh
          filename="package://urdf_arm_manipulator/meshes/link_3.STL" />
      </geometry>
      <material
        name="">
        <color
          rgba="0.75294 0.75294 0.75294 1" />
      </material>
    </visual>
    <collision>
      <origin
        xyz="0 0 0"
        rpy="0 0 0" />
      <geometry>
        <mesh
          filename="package://urdf_arm_manipulator/meshes/link_3.STL" />
      </geometry>
    </collision>
  </link>
  <joint
    name="joint_3"
    type="continuous">
    <origin
      xyz="0.0316 0 0.2992"
      rpy="0 0 0" />
    <parent
      link="link_2" />
    <child
      link="link_3" />
    <axis
      xyz="0 1 0" />
  </joint>
  <link
    name="link_4">
    <inertial>
      <origin
        xyz="-0.014002 0.00031688 0.037776"
        rpy="0 0 0" />
      <mass
        value="0.071233" />
      <inertia
        ixx="2.3081E-05"
        ixy="1.0314E-08"
        ixz="1.883E-06"
        iyy="2.3992E-05"
        iyz="1.4972E-09"
        izz="2.9268E-05" />
    </inertial>
    <visual>
      <origin
        xyz="0 0 0"
        rpy="0 0 0" />
      <geometry>
        <mesh
          filename="package://urdf_arm_manipulator/meshes/link_4.STL" />
      </geometry>
      <material
        name="">
        <color
          rgba="0.75294 0.75294 0.75294 1" />
      </material>
    </visual>
    <collision>
      <origin
        xyz="0 0 0"
        rpy="0 0 0" />
      <geometry>
        <mesh
          filename="package://urdf_arm_manipulator/meshes/link_4.STL" />
      </geometry>
    </collision>
  </link>
  <joint
    name="joint_4"
    type="continuous">
    <origin
      xyz="0.00185 0 0.2967"
      rpy="0 0 0" />
    <parent
      link="link_3" />
    <child
      link="link_4" />
    <axis
      xyz="0 -1 0" />
  </joint>
</robot>